# Linux SQLAlchemy Fix - "Already has a primary mapper defined" Error

## Problem
On Linux systems, the Flask app was failing with:
```
sqlalchemy.exc.ArgumentError: Class '<class 'app.models.user.User'>' already has a primary mapper defined.
```

## Root Cause
The issue occurs when SQLAlchemy models are imported multiple times, which can happen when:
1. Models are imported in the main app
2. Models are imported in blueprints
3. Models are imported during database initialization
4. Models are imported in different parts of the application

## Solution Applied

### 1. **Centralized Model Import**
- Moved all model imports to the `create_app()` function in `app/main.py`
- Models are imported once during app creation, before blueprints are registered
- This ensures models are registered with SQLAlchemy before any blueprint tries to use them

### 2. **Updated main.py Structure**
```python
def create_app():
    # ... app configuration ...
    
    # Initialize extensions
    db.init_app(app)
    jwt.init_app(app)
    cors.init_app(app, resources={r"/api/*": {"origins": "*"}})
    migrate.init_app(app, db)

    # Import models first to ensure they're registered with SQLAlchemy
    from app.models import User, ChatSession, ChatMessage, Log
    
    # Register blueprints (models are already imported above)
    from app.api.v1 import auth, users, sessions, messages, logs, stats, health, help, whatsapp
    from app.api.v1.hubspot import contacts_bp, companies_bp, deals_bp, notes_bp, tasks_bp, activities_bp, associations_bp, leads_bp
    
    # ... rest of blueprint registration ...
```

### 3. **Simplified Database Initialization**
```python
if __name__ == '__main__':
    with app.app_context():
        try:
            # Models are already imported in create_app()
            db.create_all()
            print("[OK] Database tables created successfully!")
        except Exception as e:
            print(f"[ERROR] Database initialization error: {e}")
```

## Key Changes Made

### 1. **app/main.py**
- âœ… Moved model imports to `create_app()` function
- âœ… Removed duplicate model imports from database initialization
- âœ… Ensured models are imported before blueprints

### 2. **Model Structure**
- âœ… All models inherit from `db.Model` (Flask-SQLAlchemy)
- âœ… Models are properly defined with `__tablename__`
- âœ… No circular imports between models

### 3. **Blueprint Structure**
- âœ… Blueprints import models from the centralized location
- âœ… No duplicate model definitions
- âœ… Proper separation of concerns

## Testing the Fix

### 1. **Run the Test Script**
```bash
python test_linux_fix.py
```

### 2. **Start the Flask App**
```bash
cd app
python main.py
```

### 3. **Expected Output**
```
[OK] Database tables created successfully!
[START] Starting Flask application...
[INFO] Server will be available at: http://127.0.0.1:5000
[INFO] Health check: http://127.0.0.1:5000/api/health
 * Running on all addresses (0.0.0.0)
 * Running on http://127.0.0.1:5000
 * Running on http://[::]:5000
```

## Why This Fix Works

### 1. **Single Import Point**
- Models are imported only once in `create_app()`
- All blueprints use the same model instances
- No duplicate SQLAlchemy mapper registration

### 2. **Proper Initialization Order**
1. Flask app created
2. Database initialized
3. Models imported and registered
4. Blueprints registered
5. Database tables created

### 3. **Linux-Specific Considerations**
- Linux has stricter import handling than Windows
- SQLAlchemy is more sensitive to duplicate imports on Linux
- This fix ensures consistent behavior across platforms

## Verification Steps

### 1. **Check Model Registration**
```python
from app.main import app
with app.app_context():
    from app.db.database import db
    print(db.Model.registry._class_registry.data)
```

### 2. **Test Database Operations**
```python
from app.models import User
user = User(name="Test", username="test", password_hash="hash", phone_number="123")
# Should work without "already has a primary mapper" error
```

### 3. **Test Blueprint Functionality**
```bash
curl http://127.0.0.1:5000/api/health
curl http://127.0.0.1:5000/api/whatsapp/status
```

## Prevention Measures

### 1. **Import Guidelines**
- âœ… Always import models from `app.models`
- âœ… Don't import models in multiple places
- âœ… Use centralized model imports

### 2. **Blueprint Guidelines**
- âœ… Import models at the top of blueprint files
- âœ… Don't redefine models in blueprints
- âœ… Use the same model instances across blueprints

### 3. **Database Guidelines**
- âœ… Import models before calling `db.create_all()`
- âœ… Use app context for database operations
- âœ… Handle import errors gracefully

## Troubleshooting

### If the error persists:

1. **Check for circular imports**
   ```bash
   python -c "from app.main import app; print('OK')"
   ```

2. **Verify model definitions**
   ```python
   from app.models import User
   print(User.__tablename__)
   ```

3. **Check SQLAlchemy registry**
   ```python
   from app.db.database import db
   print(len(db.Model.registry._class_registry.data))
   ```

## Success Indicators

- âœ… Flask app starts without SQLAlchemy errors
- âœ… Database tables are created successfully
- âœ… All API endpoints work correctly
- âœ… No "already has a primary mapper" errors
- âœ… Consistent behavior across Windows and Linux

The fix ensures that the HubSpot Logging AI Agent works reliably on both Windows and Linux systems! ðŸš€
